{"uid":"4e512a7e37e89698","name":"test_backup_aws","fullName":"tests.integration.test_backups#test_backup_aws","historyId":"bcfd49f36d62d4a7829769666ae6fe60","time":{"start":1725327431013,"stop":1725329673502,"duration":2242489},"description":"Build and deploy two units of PostgreSQL in AWS, test backup and restore actions.","descriptionHtml":"<p>Build and deploy two units of PostgreSQL in AWS, test backup and restore actions.</p>\n","status":"broken","statusMessage":"asyncio.exceptions.TimeoutError","statusTrace":"Traceback (most recent call last):\n  File \"/home/runner/work/test-runners-2-github-x64-postgresql-operator/test-runners-2-github-x64-postgresql-operator/.tox/integration/lib/python3.10/site-packages/juju/utils.py\", line 129, in _block\n    await jasyncio.sleep(wait_period)\n  File \"/usr/lib/python3.10/asyncio/tasks.py\", line 605, in sleep\n    return await future\nasyncio.exceptions.CancelledError\n\nDuring handling of the above exception, another exception occurred:\n\nTraceback (most recent call last):\n  File \"/usr/lib/python3.10/asyncio/tasks.py\", line 456, in wait_for\n    return fut.result()\nasyncio.exceptions.CancelledError\n\nThe above exception was the direct cause of the following exception:\n\nTraceback (most recent call last):\n  File \"/home/runner/work/test-runners-2-github-x64-postgresql-operator/test-runners-2-github-x64-postgresql-operator/.tox/integration/lib/python3.10/site-packages/_pytest/runner.py\", line 341, in from_call\n    result: Optional[TResult] = func()\n  File \"/home/runner/work/test-runners-2-github-x64-postgresql-operator/test-runners-2-github-x64-postgresql-operator/.tox/integration/lib/python3.10/site-packages/_pytest/runner.py\", line 241, in <lambda>\n    lambda: runtest_hook(item=item, **kwds), when=when, reraise=reraise\n  File \"/home/runner/work/test-runners-2-github-x64-postgresql-operator/test-runners-2-github-x64-postgresql-operator/.tox/integration/lib/python3.10/site-packages/pluggy/_hooks.py\", line 513, in __call__\n    return self._hookexec(self.name, self._hookimpls.copy(), kwargs, firstresult)\n  File \"/home/runner/work/test-runners-2-github-x64-postgresql-operator/test-runners-2-github-x64-postgresql-operator/.tox/integration/lib/python3.10/site-packages/pluggy/_manager.py\", line 120, in _hookexec\n    return self._inner_hookexec(hook_name, methods, kwargs, firstresult)\n  File \"/home/runner/work/test-runners-2-github-x64-postgresql-operator/test-runners-2-github-x64-postgresql-operator/.tox/integration/lib/python3.10/site-packages/pluggy/_callers.py\", line 182, in _multicall\n    return outcome.get_result()\n  File \"/home/runner/work/test-runners-2-github-x64-postgresql-operator/test-runners-2-github-x64-postgresql-operator/.tox/integration/lib/python3.10/site-packages/pluggy/_result.py\", line 100, in get_result\n    raise exc.with_traceback(exc.__traceback__)\n  File \"/home/runner/work/test-runners-2-github-x64-postgresql-operator/test-runners-2-github-x64-postgresql-operator/.tox/integration/lib/python3.10/site-packages/pluggy/_callers.py\", line 167, in _multicall\n    teardown.throw(outcome._exception)\n  File \"/home/runner/work/test-runners-2-github-x64-postgresql-operator/test-runners-2-github-x64-postgresql-operator/.tox/integration/lib/python3.10/site-packages/_pytest/threadexception.py\", line 87, in pytest_runtest_call\n    yield from thread_exception_runtest_hook()\n  File \"/home/runner/work/test-runners-2-github-x64-postgresql-operator/test-runners-2-github-x64-postgresql-operator/.tox/integration/lib/python3.10/site-packages/_pytest/threadexception.py\", line 63, in thread_exception_runtest_hook\n    yield\n  File \"/home/runner/work/test-runners-2-github-x64-postgresql-operator/test-runners-2-github-x64-postgresql-operator/.tox/integration/lib/python3.10/site-packages/pluggy/_callers.py\", line 167, in _multicall\n    teardown.throw(outcome._exception)\n  File \"/home/runner/work/test-runners-2-github-x64-postgresql-operator/test-runners-2-github-x64-postgresql-operator/.tox/integration/lib/python3.10/site-packages/_pytest/unraisableexception.py\", line 90, in pytest_runtest_call\n    yield from unraisable_exception_runtest_hook()\n  File \"/home/runner/work/test-runners-2-github-x64-postgresql-operator/test-runners-2-github-x64-postgresql-operator/.tox/integration/lib/python3.10/site-packages/_pytest/unraisableexception.py\", line 65, in unraisable_exception_runtest_hook\n    yield\n  File \"/home/runner/work/test-runners-2-github-x64-postgresql-operator/test-runners-2-github-x64-postgresql-operator/.tox/integration/lib/python3.10/site-packages/pluggy/_callers.py\", line 167, in _multicall\n    teardown.throw(outcome._exception)\n  File \"/home/runner/work/test-runners-2-github-x64-postgresql-operator/test-runners-2-github-x64-postgresql-operator/.tox/integration/lib/python3.10/site-packages/_pytest/logging.py\", line 850, in pytest_runtest_call\n    yield from self._runtest_for(item, \"call\")\n  File \"/home/runner/work/test-runners-2-github-x64-postgresql-operator/test-runners-2-github-x64-postgresql-operator/.tox/integration/lib/python3.10/site-packages/_pytest/logging.py\", line 833, in _runtest_for\n    yield\n  File \"/home/runner/work/test-runners-2-github-x64-postgresql-operator/test-runners-2-github-x64-postgresql-operator/.tox/integration/lib/python3.10/site-packages/pluggy/_callers.py\", line 167, in _multicall\n    teardown.throw(outcome._exception)\n  File \"/home/runner/work/test-runners-2-github-x64-postgresql-operator/test-runners-2-github-x64-postgresql-operator/.tox/integration/lib/python3.10/site-packages/_pytest/capture.py\", line 878, in pytest_runtest_call\n    return (yield)\n  File \"/home/runner/work/test-runners-2-github-x64-postgresql-operator/test-runners-2-github-x64-postgresql-operator/.tox/integration/lib/python3.10/site-packages/pluggy/_callers.py\", line 167, in _multicall\n    teardown.throw(outcome._exception)\n  File \"/home/runner/work/test-runners-2-github-x64-postgresql-operator/test-runners-2-github-x64-postgresql-operator/.tox/integration/lib/python3.10/site-packages/_pytest/skipping.py\", line 257, in pytest_runtest_call\n    return (yield)\n  File \"/home/runner/work/test-runners-2-github-x64-postgresql-operator/test-runners-2-github-x64-postgresql-operator/.tox/integration/lib/python3.10/site-packages/pluggy/_callers.py\", line 103, in _multicall\n    res = hook_impl.function(*args)\n  File \"/home/runner/work/test-runners-2-github-x64-postgresql-operator/test-runners-2-github-x64-postgresql-operator/.tox/integration/lib/python3.10/site-packages/_pytest/runner.py\", line 183, in pytest_runtest_call\n    raise e\n  File \"/home/runner/work/test-runners-2-github-x64-postgresql-operator/test-runners-2-github-x64-postgresql-operator/.tox/integration/lib/python3.10/site-packages/_pytest/runner.py\", line 173, in pytest_runtest_call\n    item.runtest()\n  File \"/home/runner/work/test-runners-2-github-x64-postgresql-operator/test-runners-2-github-x64-postgresql-operator/.tox/integration/lib/python3.10/site-packages/_pytest/python.py\", line 1632, in runtest\n    self.ihook.pytest_pyfunc_call(pyfuncitem=self)\n  File \"/home/runner/work/test-runners-2-github-x64-postgresql-operator/test-runners-2-github-x64-postgresql-operator/.tox/integration/lib/python3.10/site-packages/pluggy/_hooks.py\", line 513, in __call__\n    return self._hookexec(self.name, self._hookimpls.copy(), kwargs, firstresult)\n  File \"/home/runner/work/test-runners-2-github-x64-postgresql-operator/test-runners-2-github-x64-postgresql-operator/.tox/integration/lib/python3.10/site-packages/pluggy/_manager.py\", line 120, in _hookexec\n    return self._inner_hookexec(hook_name, methods, kwargs, firstresult)\n  File \"/home/runner/work/test-runners-2-github-x64-postgresql-operator/test-runners-2-github-x64-postgresql-operator/.tox/integration/lib/python3.10/site-packages/pluggy/_callers.py\", line 182, in _multicall\n    return outcome.get_result()\n  File \"/home/runner/work/test-runners-2-github-x64-postgresql-operator/test-runners-2-github-x64-postgresql-operator/.tox/integration/lib/python3.10/site-packages/pluggy/_result.py\", line 100, in get_result\n    raise exc.with_traceback(exc.__traceback__)\n  File \"/home/runner/work/test-runners-2-github-x64-postgresql-operator/test-runners-2-github-x64-postgresql-operator/.tox/integration/lib/python3.10/site-packages/pluggy/_callers.py\", line 103, in _multicall\n    res = hook_impl.function(*args)\n  File \"/home/runner/work/test-runners-2-github-x64-postgresql-operator/test-runners-2-github-x64-postgresql-operator/.tox/integration/lib/python3.10/site-packages/_pytest/python.py\", line 162, in pytest_pyfunc_call\n    result = testfunction(**testargs)\n  File \"/home/runner/work/test-runners-2-github-x64-postgresql-operator/test-runners-2-github-x64-postgresql-operator/.tox/integration/lib/python3.10/site-packages/pytest_asyncio/plugin.py\", line 529, in inner\n    _loop.run_until_complete(task)\n  File \"/usr/lib/python3.10/asyncio/base_events.py\", line 649, in run_until_complete\n    return future.result()\n  File \"/home/runner/work/test-runners-2-github-x64-postgresql-operator/test-runners-2-github-x64-postgresql-operator/tests/integration/test_backups.py\", line 131, in test_backup_aws\n    await ops_test.model.block_until(\n  File \"/home/runner/work/test-runners-2-github-x64-postgresql-operator/test-runners-2-github-x64-postgresql-operator/.tox/integration/lib/python3.10/site-packages/juju/model.py\", line 1045, in block_until\n    await utils.block_until(done,\n  File \"/home/runner/work/test-runners-2-github-x64-postgresql-operator/test-runners-2-github-x64-postgresql-operator/.tox/integration/lib/python3.10/site-packages/juju/utils.py\", line 130, in block_until\n    await jasyncio.shield(jasyncio.wait_for(_block(), timeout))\n  File \"/usr/lib/python3.10/asyncio/tasks.py\", line 458, in wait_for\n    raise exceptions.TimeoutError() from exc\nasyncio.exceptions.TimeoutError","flaky":false,"newFailed":false,"newBroken":false,"newPassed":false,"retriesCount":1,"retriesStatusChange":true,"beforeStages":[{"name":"event_loop","time":{"start":1725327430755,"stop":1725327430756,"duration":1},"status":"passed","steps":[],"attachments":[],"parameters":[],"stepsCount":0,"shouldDisplayMessage":false,"attachmentsCount":0,"hasContent":false,"attachmentStep":false},{"name":"ops_test","time":{"start":1725327430756,"stop":1725327430922,"duration":166},"status":"passed","steps":[],"attachments":[],"parameters":[],"stepsCount":0,"shouldDisplayMessage":false,"attachmentsCount":0,"hasContent":false,"attachmentStep":false},{"name":"tmp_path_factory","time":{"start":1725327430756,"stop":1725327430756,"duration":0},"status":"passed","steps":[],"attachments":[],"parameters":[],"stepsCount":0,"shouldDisplayMessage":false,"attachmentsCount":0,"hasContent":false,"attachmentStep":false},{"name":"github_secrets","time":{"start":1725327430756,"stop":1725327430756,"duration":0},"status":"passed","steps":[],"attachments":[],"parameters":[],"stepsCount":0,"shouldDisplayMessage":false,"attachmentsCount":0,"hasContent":false,"attachmentStep":false},{"name":"cloud_configs","time":{"start":1725327430922,"stop":1725327431010,"duration":88},"status":"passed","steps":[],"attachments":[],"parameters":[],"stepsCount":0,"shouldDisplayMessage":false,"attachmentsCount":0,"hasContent":false,"attachmentStep":false},{"name":"charm","time":{"start":1725327431010,"stop":1725327431012,"duration":2},"status":"passed","steps":[],"attachments":[],"parameters":[],"stepsCount":0,"shouldDisplayMessage":false,"attachmentsCount":0,"hasContent":false,"attachmentStep":false},{"name":"abort_on_fail","time":{"start":1725327431012,"stop":1725327431013,"duration":1},"status":"passed","steps":[],"attachments":[],"parameters":[],"stepsCount":0,"shouldDisplayMessage":false,"attachmentsCount":0,"hasContent":false,"attachmentStep":false}],"testStage":{"description":"Build and deploy two units of PostgreSQL in AWS, test backup and restore actions.","status":"broken","statusMessage":"asyncio.exceptions.TimeoutError","statusTrace":"Traceback (most recent call last):\n  File \"/home/runner/work/test-runners-2-github-x64-postgresql-operator/test-runners-2-github-x64-postgresql-operator/.tox/integration/lib/python3.10/site-packages/juju/utils.py\", line 129, in _block\n    await jasyncio.sleep(wait_period)\n  File \"/usr/lib/python3.10/asyncio/tasks.py\", line 605, in sleep\n    return await future\nasyncio.exceptions.CancelledError\n\nDuring handling of the above exception, another exception occurred:\n\nTraceback (most recent call last):\n  File \"/usr/lib/python3.10/asyncio/tasks.py\", line 456, in wait_for\n    return fut.result()\nasyncio.exceptions.CancelledError\n\nThe above exception was the direct cause of the following exception:\n\nTraceback (most recent call last):\n  File \"/home/runner/work/test-runners-2-github-x64-postgresql-operator/test-runners-2-github-x64-postgresql-operator/.tox/integration/lib/python3.10/site-packages/_pytest/runner.py\", line 341, in from_call\n    result: Optional[TResult] = func()\n  File \"/home/runner/work/test-runners-2-github-x64-postgresql-operator/test-runners-2-github-x64-postgresql-operator/.tox/integration/lib/python3.10/site-packages/_pytest/runner.py\", line 241, in <lambda>\n    lambda: runtest_hook(item=item, **kwds), when=when, reraise=reraise\n  File \"/home/runner/work/test-runners-2-github-x64-postgresql-operator/test-runners-2-github-x64-postgresql-operator/.tox/integration/lib/python3.10/site-packages/pluggy/_hooks.py\", line 513, in __call__\n    return self._hookexec(self.name, self._hookimpls.copy(), kwargs, firstresult)\n  File \"/home/runner/work/test-runners-2-github-x64-postgresql-operator/test-runners-2-github-x64-postgresql-operator/.tox/integration/lib/python3.10/site-packages/pluggy/_manager.py\", line 120, in _hookexec\n    return self._inner_hookexec(hook_name, methods, kwargs, firstresult)\n  File \"/home/runner/work/test-runners-2-github-x64-postgresql-operator/test-runners-2-github-x64-postgresql-operator/.tox/integration/lib/python3.10/site-packages/pluggy/_callers.py\", line 182, in _multicall\n    return outcome.get_result()\n  File \"/home/runner/work/test-runners-2-github-x64-postgresql-operator/test-runners-2-github-x64-postgresql-operator/.tox/integration/lib/python3.10/site-packages/pluggy/_result.py\", line 100, in get_result\n    raise exc.with_traceback(exc.__traceback__)\n  File \"/home/runner/work/test-runners-2-github-x64-postgresql-operator/test-runners-2-github-x64-postgresql-operator/.tox/integration/lib/python3.10/site-packages/pluggy/_callers.py\", line 167, in _multicall\n    teardown.throw(outcome._exception)\n  File \"/home/runner/work/test-runners-2-github-x64-postgresql-operator/test-runners-2-github-x64-postgresql-operator/.tox/integration/lib/python3.10/site-packages/_pytest/threadexception.py\", line 87, in pytest_runtest_call\n    yield from thread_exception_runtest_hook()\n  File \"/home/runner/work/test-runners-2-github-x64-postgresql-operator/test-runners-2-github-x64-postgresql-operator/.tox/integration/lib/python3.10/site-packages/_pytest/threadexception.py\", line 63, in thread_exception_runtest_hook\n    yield\n  File \"/home/runner/work/test-runners-2-github-x64-postgresql-operator/test-runners-2-github-x64-postgresql-operator/.tox/integration/lib/python3.10/site-packages/pluggy/_callers.py\", line 167, in _multicall\n    teardown.throw(outcome._exception)\n  File \"/home/runner/work/test-runners-2-github-x64-postgresql-operator/test-runners-2-github-x64-postgresql-operator/.tox/integration/lib/python3.10/site-packages/_pytest/unraisableexception.py\", line 90, in pytest_runtest_call\n    yield from unraisable_exception_runtest_hook()\n  File \"/home/runner/work/test-runners-2-github-x64-postgresql-operator/test-runners-2-github-x64-postgresql-operator/.tox/integration/lib/python3.10/site-packages/_pytest/unraisableexception.py\", line 65, in unraisable_exception_runtest_hook\n    yield\n  File \"/home/runner/work/test-runners-2-github-x64-postgresql-operator/test-runners-2-github-x64-postgresql-operator/.tox/integration/lib/python3.10/site-packages/pluggy/_callers.py\", line 167, in _multicall\n    teardown.throw(outcome._exception)\n  File \"/home/runner/work/test-runners-2-github-x64-postgresql-operator/test-runners-2-github-x64-postgresql-operator/.tox/integration/lib/python3.10/site-packages/_pytest/logging.py\", line 850, in pytest_runtest_call\n    yield from self._runtest_for(item, \"call\")\n  File \"/home/runner/work/test-runners-2-github-x64-postgresql-operator/test-runners-2-github-x64-postgresql-operator/.tox/integration/lib/python3.10/site-packages/_pytest/logging.py\", line 833, in _runtest_for\n    yield\n  File \"/home/runner/work/test-runners-2-github-x64-postgresql-operator/test-runners-2-github-x64-postgresql-operator/.tox/integration/lib/python3.10/site-packages/pluggy/_callers.py\", line 167, in _multicall\n    teardown.throw(outcome._exception)\n  File \"/home/runner/work/test-runners-2-github-x64-postgresql-operator/test-runners-2-github-x64-postgresql-operator/.tox/integration/lib/python3.10/site-packages/_pytest/capture.py\", line 878, in pytest_runtest_call\n    return (yield)\n  File \"/home/runner/work/test-runners-2-github-x64-postgresql-operator/test-runners-2-github-x64-postgresql-operator/.tox/integration/lib/python3.10/site-packages/pluggy/_callers.py\", line 167, in _multicall\n    teardown.throw(outcome._exception)\n  File \"/home/runner/work/test-runners-2-github-x64-postgresql-operator/test-runners-2-github-x64-postgresql-operator/.tox/integration/lib/python3.10/site-packages/_pytest/skipping.py\", line 257, in pytest_runtest_call\n    return (yield)\n  File \"/home/runner/work/test-runners-2-github-x64-postgresql-operator/test-runners-2-github-x64-postgresql-operator/.tox/integration/lib/python3.10/site-packages/pluggy/_callers.py\", line 103, in _multicall\n    res = hook_impl.function(*args)\n  File \"/home/runner/work/test-runners-2-github-x64-postgresql-operator/test-runners-2-github-x64-postgresql-operator/.tox/integration/lib/python3.10/site-packages/_pytest/runner.py\", line 183, in pytest_runtest_call\n    raise e\n  File \"/home/runner/work/test-runners-2-github-x64-postgresql-operator/test-runners-2-github-x64-postgresql-operator/.tox/integration/lib/python3.10/site-packages/_pytest/runner.py\", line 173, in pytest_runtest_call\n    item.runtest()\n  File \"/home/runner/work/test-runners-2-github-x64-postgresql-operator/test-runners-2-github-x64-postgresql-operator/.tox/integration/lib/python3.10/site-packages/_pytest/python.py\", line 1632, in runtest\n    self.ihook.pytest_pyfunc_call(pyfuncitem=self)\n  File \"/home/runner/work/test-runners-2-github-x64-postgresql-operator/test-runners-2-github-x64-postgresql-operator/.tox/integration/lib/python3.10/site-packages/pluggy/_hooks.py\", line 513, in __call__\n    return self._hookexec(self.name, self._hookimpls.copy(), kwargs, firstresult)\n  File \"/home/runner/work/test-runners-2-github-x64-postgresql-operator/test-runners-2-github-x64-postgresql-operator/.tox/integration/lib/python3.10/site-packages/pluggy/_manager.py\", line 120, in _hookexec\n    return self._inner_hookexec(hook_name, methods, kwargs, firstresult)\n  File \"/home/runner/work/test-runners-2-github-x64-postgresql-operator/test-runners-2-github-x64-postgresql-operator/.tox/integration/lib/python3.10/site-packages/pluggy/_callers.py\", line 182, in _multicall\n    return outcome.get_result()\n  File \"/home/runner/work/test-runners-2-github-x64-postgresql-operator/test-runners-2-github-x64-postgresql-operator/.tox/integration/lib/python3.10/site-packages/pluggy/_result.py\", line 100, in get_result\n    raise exc.with_traceback(exc.__traceback__)\n  File \"/home/runner/work/test-runners-2-github-x64-postgresql-operator/test-runners-2-github-x64-postgresql-operator/.tox/integration/lib/python3.10/site-packages/pluggy/_callers.py\", line 103, in _multicall\n    res = hook_impl.function(*args)\n  File \"/home/runner/work/test-runners-2-github-x64-postgresql-operator/test-runners-2-github-x64-postgresql-operator/.tox/integration/lib/python3.10/site-packages/_pytest/python.py\", line 162, in pytest_pyfunc_call\n    result = testfunction(**testargs)\n  File \"/home/runner/work/test-runners-2-github-x64-postgresql-operator/test-runners-2-github-x64-postgresql-operator/.tox/integration/lib/python3.10/site-packages/pytest_asyncio/plugin.py\", line 529, in inner\n    _loop.run_until_complete(task)\n  File \"/usr/lib/python3.10/asyncio/base_events.py\", line 649, in run_until_complete\n    return future.result()\n  File \"/home/runner/work/test-runners-2-github-x64-postgresql-operator/test-runners-2-github-x64-postgresql-operator/tests/integration/test_backups.py\", line 131, in test_backup_aws\n    await ops_test.model.block_until(\n  File \"/home/runner/work/test-runners-2-github-x64-postgresql-operator/test-runners-2-github-x64-postgresql-operator/.tox/integration/lib/python3.10/site-packages/juju/model.py\", line 1045, in block_until\n    await utils.block_until(done,\n  File \"/home/runner/work/test-runners-2-github-x64-postgresql-operator/test-runners-2-github-x64-postgresql-operator/.tox/integration/lib/python3.10/site-packages/juju/utils.py\", line 130, in block_until\n    await jasyncio.shield(jasyncio.wait_for(_block(), timeout))\n  File \"/usr/lib/python3.10/asyncio/tasks.py\", line 458, in wait_for\n    raise exceptions.TimeoutError() from exc\nasyncio.exceptions.TimeoutError","steps":[],"attachments":[{"uid":"b4c4239202c623f9","name":"log","source":"b4c4239202c623f9.txt","type":"text/plain","size":11209}],"parameters":[],"stepsCount":0,"shouldDisplayMessage":true,"attachmentsCount":1,"hasContent":true,"attachmentStep":false},"afterStages":[{"name":"charm::finalizer","time":{"start":1725329673527,"stop":1725329673527,"duration":0},"status":"passed","steps":[],"attachments":[],"parameters":[],"stepsCount":0,"shouldDisplayMessage":false,"attachmentsCount":0,"hasContent":false,"attachmentStep":false},{"name":"abort_on_fail::0","time":{"start":1725329673527,"stop":1725329673527,"duration":0},"status":"passed","steps":[],"attachments":[],"parameters":[],"stepsCount":0,"shouldDisplayMessage":false,"attachmentsCount":0,"hasContent":false,"attachmentStep":false},{"name":"cloud_configs::finalizer","time":{"start":1725329673528,"stop":1725329674657,"duration":1129},"status":"broken","statusMessage":"botocore.exceptions.NoCredentialsError: Unable to locate credentials\n","statusTrace":"  File \"/home/runner/work/test-runners-2-github-x64-postgresql-operator/test-runners-2-github-x64-postgresql-operator/.tox/integration/lib/python3.10/site-packages/allure_commons/_allure.py\", line 221, in __call__\n    return self._fixture_function(*args, **kwargs)\n  File \"/home/runner/work/test-runners-2-github-x64-postgresql-operator/test-runners-2-github-x64-postgresql-operator/.tox/integration/lib/python3.10/site-packages/pytest_asyncio/plugin.py\", line 300, in finalizer\n    event_loop.run_until_complete(async_finalizer())\n  File \"/usr/lib/python3.10/asyncio/base_events.py\", line 649, in run_until_complete\n    return future.result()\n  File \"/home/runner/work/test-runners-2-github-x64-postgresql-operator/test-runners-2-github-x64-postgresql-operator/.tox/integration/lib/python3.10/site-packages/pytest_asyncio/plugin.py\", line 292, in async_finalizer\n    await gen_obj.__anext__()\n  File \"/home/runner/work/test-runners-2-github-x64-postgresql-operator/test-runners-2-github-x64-postgresql-operator/tests/integration/test_backups.py\", line 96, in cloud_configs\n    for bucket_object in bucket.objects.filter(Prefix=config[\"path\"].lstrip(\"/\")):\n  File \"/home/runner/work/test-runners-2-github-x64-postgresql-operator/test-runners-2-github-x64-postgresql-operator/.tox/integration/lib/python3.10/site-packages/boto3/resources/collection.py\", line 79, in __iter__\n    for page in self.pages():\n  File \"/home/runner/work/test-runners-2-github-x64-postgresql-operator/test-runners-2-github-x64-postgresql-operator/.tox/integration/lib/python3.10/site-packages/boto3/resources/collection.py\", line 169, in pages\n    for page in pages:\n  File \"/home/runner/work/test-runners-2-github-x64-postgresql-operator/test-runners-2-github-x64-postgresql-operator/.tox/integration/lib/python3.10/site-packages/botocore/paginate.py\", line 269, in __iter__\n    response = self._make_request(current_kwargs)\n  File \"/home/runner/work/test-runners-2-github-x64-postgresql-operator/test-runners-2-github-x64-postgresql-operator/.tox/integration/lib/python3.10/site-packages/botocore/paginate.py\", line 357, in _make_request\n    return self._method(**current_kwargs)\n  File \"/home/runner/work/test-runners-2-github-x64-postgresql-operator/test-runners-2-github-x64-postgresql-operator/.tox/integration/lib/python3.10/site-packages/botocore/client.py\", line 565, in _api_call\n    return self._make_api_call(operation_name, kwargs)\n  File \"/home/runner/work/test-runners-2-github-x64-postgresql-operator/test-runners-2-github-x64-postgresql-operator/.tox/integration/lib/python3.10/site-packages/botocore/client.py\", line 1001, in _make_api_call\n    http, parsed_response = self._make_request(\n  File \"/home/runner/work/test-runners-2-github-x64-postgresql-operator/test-runners-2-github-x64-postgresql-operator/.tox/integration/lib/python3.10/site-packages/botocore/client.py\", line 1027, in _make_request\n    return self._endpoint.make_request(operation_model, request_dict)\n  File \"/home/runner/work/test-runners-2-github-x64-postgresql-operator/test-runners-2-github-x64-postgresql-operator/.tox/integration/lib/python3.10/site-packages/botocore/endpoint.py\", line 119, in make_request\n    return self._send_request(request_dict, operation_model)\n  File \"/home/runner/work/test-runners-2-github-x64-postgresql-operator/test-runners-2-github-x64-postgresql-operator/.tox/integration/lib/python3.10/site-packages/botocore/endpoint.py\", line 198, in _send_request\n    request = self.create_request(request_dict, operation_model)\n  File \"/home/runner/work/test-runners-2-github-x64-postgresql-operator/test-runners-2-github-x64-postgresql-operator/.tox/integration/lib/python3.10/site-packages/botocore/endpoint.py\", line 134, in create_request\n    self._event_emitter.emit(\n  File \"/home/runner/work/test-runners-2-github-x64-postgresql-operator/test-runners-2-github-x64-postgresql-operator/.tox/integration/lib/python3.10/site-packages/botocore/hooks.py\", line 412, in emit\n    return self._emitter.emit(aliased_event_name, **kwargs)\n  File \"/home/runner/work/test-runners-2-github-x64-postgresql-operator/test-runners-2-github-x64-postgresql-operator/.tox/integration/lib/python3.10/site-packages/botocore/hooks.py\", line 256, in emit\n    return self._emit(event_name, kwargs)\n  File \"/home/runner/work/test-runners-2-github-x64-postgresql-operator/test-runners-2-github-x64-postgresql-operator/.tox/integration/lib/python3.10/site-packages/botocore/hooks.py\", line 239, in _emit\n    response = handler(**kwargs)\n  File \"/home/runner/work/test-runners-2-github-x64-postgresql-operator/test-runners-2-github-x64-postgresql-operator/.tox/integration/lib/python3.10/site-packages/botocore/signers.py\", line 105, in handler\n    return self.sign(operation_name, request)\n  File \"/home/runner/work/test-runners-2-github-x64-postgresql-operator/test-runners-2-github-x64-postgresql-operator/.tox/integration/lib/python3.10/site-packages/botocore/signers.py\", line 199, in sign\n    auth.add_auth(request)\n  File \"/home/runner/work/test-runners-2-github-x64-postgresql-operator/test-runners-2-github-x64-postgresql-operator/.tox/integration/lib/python3.10/site-packages/botocore/auth.py\", line 418, in add_auth\n    raise NoCredentialsError()\n","steps":[],"attachments":[],"parameters":[],"stepsCount":0,"shouldDisplayMessage":true,"attachmentsCount":0,"hasContent":true,"attachmentStep":false},{"name":"ops_test::finalizer","time":{"start":1725329674658,"stop":1725329674990,"duration":332},"status":"passed","steps":[],"attachments":[],"parameters":[],"stepsCount":0,"shouldDisplayMessage":false,"attachmentsCount":0,"hasContent":false,"attachmentStep":false},{"name":"event_loop::2","time":{"start":1725329674991,"stop":1725329674991,"duration":0},"status":"passed","steps":[],"attachments":[],"parameters":[],"stepsCount":0,"shouldDisplayMessage":false,"attachmentsCount":0,"hasContent":false,"attachmentStep":false},{"name":"event_loop::_close_event_loop","time":{"start":1725329674991,"stop":1725329674991,"duration":0},"status":"passed","steps":[],"attachments":[],"parameters":[],"stepsCount":0,"shouldDisplayMessage":false,"attachmentsCount":0,"hasContent":false,"attachmentStep":false},{"name":"event_loop::_provide_clean_event_loop","time":{"start":1725329674991,"stop":1725329674992,"duration":1},"status":"passed","steps":[],"attachments":[],"parameters":[],"stepsCount":0,"shouldDisplayMessage":false,"attachmentsCount":0,"hasContent":false,"attachmentStep":false}],"labels":[{"name":"tag","value":"abort_on_fail"},{"name":"tag","value":"group(1)"},{"name":"tag","value":"asyncio"},{"name":"parentSuite","value":"tests.integration"},{"name":"suite","value":"test_backups"},{"name":"host","value":"fv-az570-490"},{"name":"thread","value":"9169-MainThread"},{"name":"framework","value":"pytest"},{"name":"language","value":"cpython3"},{"name":"package","value":"tests.integration.test_backups"},{"name":"resultFormat","value":"allure2"}],"parameters":[],"links":[],"hidden":false,"retry":false,"extra":{"severity":"normal","retries":[{"uid":"e4b4bb7ff1b65d15","status":"unknown","time":{}}],"categories":[{"name":"Test defects","matchedStatuses":[],"flaky":false}],"history":{"statistic":{"failed":0,"broken":45,"skipped":0,"passed":0,"unknown":2,"total":47},"items":[{"uid":"12fa298a4e5ca2bb","reportUrl":"../161//#testresult/12fa298a4e5ca2bb","status":"broken","statusDetails":"botocore.exceptions.NoCredentialsError: Unable to locate credentials","time":{"start":1725241028047,"stop":1725243052318,"duration":2024271}},{"uid":"fea0da435de2bc72","reportUrl":"../160//#testresult/fea0da435de2bc72","status":"broken","statusDetails":"botocore.exceptions.NoCredentialsError: Unable to locate credentials","time":{"start":1725154666094,"stop":1725156089067,"duration":1422973}},{"uid":"70d7248c9db213f5","reportUrl":"../159//#testresult/70d7248c9db213f5","status":"broken","statusDetails":"botocore.exceptions.NoCredentialsError: Unable to locate credentials","time":{"start":1725068224284,"stop":1725070064852,"duration":1840568}},{"uid":"8a368d745540813c","reportUrl":"../158//#testresult/8a368d745540813c","status":"broken","statusDetails":"botocore.exceptions.NoCredentialsError: Unable to locate credentials","time":{"start":1724981850252,"stop":1724983482129,"duration":1631877}},{"uid":"33886268352243a6","reportUrl":"../157//#testresult/33886268352243a6","status":"broken","statusDetails":"botocore.exceptions.NoCredentialsError: Unable to locate credentials","time":{"start":1724895388856,"stop":1724896865730,"duration":1476874}},{"uid":"a83994dc94b38a76","reportUrl":"../156//#testresult/a83994dc94b38a76","status":"broken","statusDetails":"asyncio.exceptions.TimeoutError","time":{"start":1724809035891,"stop":1724811026077,"duration":1990186}},{"uid":"4100ce3174983059","reportUrl":"../155//#testresult/4100ce3174983059","status":"broken","statusDetails":"botocore.exceptions.NoCredentialsError: Unable to locate credentials","time":{"start":1724722643685,"stop":1724724467885,"duration":1824200}},{"uid":"abb35e770af599ce","reportUrl":"../154//#testresult/abb35e770af599ce","status":"broken","statusDetails":"botocore.exceptions.NoCredentialsError: Unable to locate credentials","time":{"start":1724636178812,"stop":1724637611964,"duration":1433152}},{"uid":"ac1f62b94c748169","reportUrl":"../153//#testresult/ac1f62b94c748169","status":"unknown","time":{}},{"uid":"e4cdbd935eb84149","reportUrl":"../152//#testresult/e4cdbd935eb84149","status":"broken","statusDetails":"juju.errors.JujuUnitError: Unit in error: postgresql-aws/1","time":{"start":1724463346256,"stop":1724463559977,"duration":213721}},{"uid":"d3a900c8d81a001f","reportUrl":"../151//#testresult/d3a900c8d81a001f","status":"broken","statusDetails":"botocore.exceptions.NoCredentialsError: Unable to locate credentials","time":{"start":1724377002881,"stop":1724378512058,"duration":1509177}},{"uid":"b6290a9ec9558c00","reportUrl":"../150//#testresult/b6290a9ec9558c00","status":"broken","statusDetails":"psycopg2.OperationalError: connection to server at \"10.179.193.129\", port 5432 failed: Connection refused\n\tIs the server running on that host and accepting TCP/IP connections?","time":{"start":1724290562373,"stop":1724292188028,"duration":1625655}},{"uid":"3caece345dd58143","reportUrl":"../149//#testresult/3caece345dd58143","status":"broken","statusDetails":"botocore.exceptions.NoCredentialsError: Unable to locate credentials","time":{"start":1724204168638,"stop":1724205644838,"duration":1476200}},{"uid":"35e4872a339775a3","reportUrl":"../148//#testresult/35e4872a339775a3","status":"broken","statusDetails":"botocore.exceptions.NoCredentialsError: Unable to locate credentials","time":{"start":1724118037475,"stop":1724119434847,"duration":1397372}},{"uid":"8403eba9d4dd5d71","reportUrl":"../147//#testresult/8403eba9d4dd5d71","status":"broken","statusDetails":"botocore.exceptions.NoCredentialsError: Unable to locate credentials","time":{"start":1724031370217,"stop":1724032787814,"duration":1417597}},{"uid":"ca53df8e5ee6c3ba","reportUrl":"../146//#testresult/ca53df8e5ee6c3ba","status":"broken","statusDetails":"botocore.exceptions.NoCredentialsError: Unable to locate credentials","time":{"start":1723945074125,"stop":1723946631107,"duration":1556982}},{"uid":"741005e8d84847b9","reportUrl":"../145//#testresult/741005e8d84847b9","status":"broken","statusDetails":"botocore.exceptions.NoCredentialsError: Unable to locate credentials","time":{"start":1723858635628,"stop":1723860315199,"duration":1679571}},{"uid":"4ffc5603efcbfc65","reportUrl":"../144//#testresult/4ffc5603efcbfc65","status":"broken","statusDetails":"botocore.exceptions.NoCredentialsError: Unable to locate credentials","time":{"start":1723772217498,"stop":1723773579717,"duration":1362219}},{"uid":"11181f3ec3232106","reportUrl":"../143//#testresult/11181f3ec3232106","status":"broken","statusDetails":"psycopg2.OperationalError: connection to server at \"10.6.34.81\", port 5432 failed: Connection refused\n\tIs the server running on that host and accepting TCP/IP connections?","time":{"start":1723685835537,"stop":1723687110023,"duration":1274486}},{"uid":"b079d8240e75d25f","reportUrl":"../142//#testresult/b079d8240e75d25f","status":"broken","statusDetails":"botocore.exceptions.NoCredentialsError: Unable to locate credentials","time":{"start":1723599689079,"stop":1723601032470,"duration":1343391}}]},"tags":["asyncio","abort_on_fail","group(1)"]},"source":"4e512a7e37e89698.json","parameterValues":[]}